<mujoco model="marv">
  <compiler angle="radian" coordinate="local" inertiafromgeom="true" meshdir="../meshes"/>
  <option integrator="RK4" timestep="0.01" o_solimp="0 0.95 0.001 0.5 2" o_solref="0.02 1"/>
  <size nconmax="300"/>

  <default>
    <joint armature="0.5" damping="3" limited="true"/>
    <geom conaffinity="0" condim="3" density="5.0" friction="1 0.5 0.5" margin="0.001" rgba="0.0 0.6 0.4 1"/>
  </default>

  <asset>
    <texture type="skybox" builtin="gradient" width="100" height="100" rgb1="1 1 1" rgb2="0 0 0" />
    <texture name="texplane" type="2d" builtin="checker" rgb1="0.26 0.12 0.36" rgb2="0.23 0.09 0.33" width="512" height="512" mark="cross" markrgb=".8 .8 .8"/>
    <texture name="texgeom" type="cube" builtin="flat" mark="cross" width="127" height="1278" rgb1="0.8 0.6 0.4" rgb2="0.8 0.6 0.4" markrgb="1 1 1" random="0.01"/>
    <material name="matplane" reflectance="0.3" texture="texplane" texrepeat="1 1" texuniform="true"/>
    <material name='geom' texture="texgeom" texuniform="true" />
    <mesh name="flipper_mesh" file="flipper.stl"/>
    <mesh name="chassis_mesh" file="chassis.stl"/>
  </asset>

  <worldbody>
    <light cutoff="100" diffuse="1 1 1" dir="-0 0 -1.3" directional="true" exponent="1" pos="0 0 1.3" specular=".1 .1 .1"/>
    <geom conaffinity="1" condim="3" material="matplane" name="floor" pos="0 0 0" size="40 40 40" type="plane"/>
    <body name="torso" pos="0 0 0">
      <camera name="track" mode="track" pos="1 -7 3.2" xyaxes="1 0 0 0 0.5 1"/>
      <geom name="torso" pos="0 0 0" size="0.3 0.18 0.1" mass="1" type="box"/>
      <geom name="torso_upper" pos="0 0 0.15" size="0.1 0.15 0.075" mass="20" type="box"/>
      <geom name="batteries" pos="0 0 0.05" size="0.05 0.05 0.01" mass="10" type="box"/>
      <geom name="tail" pos="-0.256 0 0" size="0.03" mass="0.1" type="sphere"/>
      <joint armature="0" damping="0" limited="false" margin="0.01" name="root" pos="0 0 0" type="free"/>

      <!-- FL flipper -->
      <body name="front_left_flipper" pos="0.256 0.245 -0.0565">
	  <geom name="front_left_flipper" fromto="0.0 0.0 0.0 0.3 0.0 0.0" size="0.05" mass="1" type="capsule"/>
        <joint axis="0 1 0" name="front_left_flipper" pos="0.0 0.0 0.0" limited="false" damping="25.0" armature= "0.1" type="hinge"/>
          <body pos="0 0 0">
            <joint axis="0 1 0" name="rear_wheel_fl" pos="0.0 0.0 0.0" limited="false" type="hinge"/>
            <geom conaffinity="1" fromto="0.0 -0.0325 0.0 0.0 0.0325 0.0" name="rear_wheel_fl" size="0.1165" mass="0.5" type="cylinder"/>
          </body>
	    <body pos="0.3 0 0">
            <joint axis="0 1 0" name="front_wheel_fl" pos="0.0 0.0 0.0" limited="false" type="hinge"/>
            <geom conaffinity="1" fromto="0.0 -0.0325 0.0 0.0 0.0325 0.0" name="front_wheel_fl" size="0.08"  mass="0.5" type="cylinder"/>
        </body>
      </body>

      <!-- FR flipper -->
      <body name="front_right_flipper" pos="0.256 -0.245 -0.0565">
	  <geom name="front_right_flipper" fromto="0.0 0.0 0.0 0.3 0.0 0.0" size="0.05" mass="1" type="capsule"/>
        <joint axis="0 1 0" name="front_right_flipper" pos="0.0 0.0 0.0" limited="false" damping="25.0" armature= "0.1" type="hinge"/>
          <body pos="0 0 0">
            <joint axis="0 1 0" name="rear_wheel_fr" pos="0.0 0.0 0.0" limited="false" type="hinge"/>
            <geom conaffinity="1" fromto="0.0 -0.0325 0.0 0.0 0.0325 0.0" name="rear_wheel_fr" size="0.1165" mass="0.5" type="cylinder"/>
          </body>
	    <body pos="0.3 0 0">
            <joint axis="0 1 0" name="front_wheel_fr" pos="0.0 0.0 0.0" limited="false" type="hinge"/>
            <geom conaffinity="1" fromto="0.0 -0.0325 0.0 0.0 0.0325 0.0" name="front_wheel_fr" size="0.08"  mass="0.5" type="cylinder"/>
        </body>
      </body>

      <!-- RL flipper -->
      <body name="rear_left_flipper" pos="-0.256 0.245 -0.0565">
	  <geom name="rear_left_flipper" fromto="0.0 0.0 0.0 0.3 0.0 0.0" size="0.05" mass="1" type="capsule"/>
        <joint axis="0 1 0" name="rear_left_flipper" pos="0.0 0.0 0.0" limited="false" damping="25.0" armature= "0.1" type="hinge"/>
          <body pos="0 0 0">
            <joint axis="0 1 0" name="rear_wheel_rl" pos="0.0 0.0 0.0" limited="false" type="hinge"/>
            <geom conaffinity="1" fromto="0.0 -0.0325 0.0 0.0 0.0325 0.0" name="rear_wheel_rl" size="0.1165" mass="0.5" type="cylinder"/>
          </body>
	    <body pos="0.3 0 0">
            <joint axis="0 1 0" name="front_wheel_rl" pos="0.0 0.0 0.0" limited="false" type="hinge"/>
            <geom conaffinity="1" fromto="0.0 -0.0325 0.0 0.0 0.0325 0.0" name="front_wheel_rl" size="0.08" mass="0.5"  type="cylinder"/>
        </body>
      </body>

      <!-- RR flipper -->
      <body name="rear_right_flipper" pos="-0.256 -0.245 -0.0565">
	  <geom name="rear_right_flipper" fromto="0.0 0.0 0.0 0.3 0.0 0.0" size="0.05" mass="1" type="capsule"/>
        <joint axis="0 1 0" name="rear_right_flipper" pos="0.0 0.0 0.0" limited="false"  damping="25.0" armature= "0.1" type="hinge"/>
          <body pos="0 0 0">
            <joint axis="0 1 0" name="rear_wheel_rr" pos="0.0 0.0 0.0" limited="false" type="hinge"/>
            <geom conaffinity="1" fromto="0.0 -0.0325 0.0 0.0 0.0325 0.0" name="rear_wheel_rr" size="0.1165" mass="0.5" type="cylinder"/>
          </body>
	    <body pos="0.3 0 0">
            <joint axis="0 1 0" name="front_wheel_rr" pos="0.0 0.0 0.0" limited="false" type="hinge"/>
            <geom conaffinity="1" fromto="0.0 -0.0325 0.0 0.0 0.0325 0.0" name="front_wheel_rr" size="0.08" mass="0.5" type="cylinder"/>
        </body>
      </body>

    </body>
  </worldbody>
  <actuator>
    <velocity joint="front_left_flipper" kv="1000" gear="0.09" forcerange="-200 200"/>
    <velocity joint="front_right_flipper" kv="1000" gear="0.09" forcerange="-200 200"/>
    <velocity joint="rear_left_flipper" kv="1000" gear="0.09" forcerange="-200 200"/>
    <velocity joint="rear_right_flipper" kv="1000" gear="0.09" forcerange="-200 200"/>
  </actuator>
</mujoco>
